
## Cancellation

### Вопрос №1
**Отработает ли строка `// <--`?**  
Нет, не отработает.

**Объяснение:**  
При вызове `job.cancelAndJoin()` отменяется вся корутина и все её дочерние корутины. Обе дочерние корутины внутри `launch` блоков будут отменены до того, как успеют выполнить свои задержки и печать.

### Вопрос №2
**Отработает ли строка `// <--`?**  
Нет, не отработает.

**Объяснение:**  
Хотя мы отменяем только конкретную дочернюю корутину `child`, вторая дочерняя корутина всё равно будет отменена, потому что родительская корутина `job` завершится (после `delay(100)` и `child.cancel()`), не дожидаясь завершения второй дочерней корутины. Когда родительская корутина завершается, все её дочерние корутины также отменяются.

## Exception Handling

### Вопрос №1
**Отработает ли строка `// <--`?**  
Нет, не отработает.

**Объяснение:**  
Исключения в корутинах не могут быть перехвачены обычным try-catch блоком вне корутины. Исключение будет передано в обработчик необработанных исключений корутин.

### Вопрос №2
**Отработает ли строка `// <--`?**  
Да, отработает.

**Объяснение:**  
`coroutineScope` перебрасывает исключения из своего блока в вызывающую корутину, поэтому они могут быть перехвачены try-catch внутри корутины.

### Вопрос №3
**Отработает ли строка `// <--`?**  
Да, отработает.

**Объяснение:**  
Аналогично `coroutineScope`, `supervisorScope` также перебрасывает исключения из своего блока в вызывающую корутину, поэтому они могут быть перехвачены try-catch.

### Вопрос №4
**Отработает ли строка `// <--`?**  
Нет, не отработает.

**Объяснение:**  
Когда одна из дочерних корутин внутри `coroutineScope` выбрасывает исключение, оно немедленно отменяет все другие дочерние корутины и само `coroutineScope`. Поэтому вторая корутина с задержкой 500 мс не успеет выполниться до того, как всё будет отменено.

### Вопрос №5
**Отработает ли строка `// <--` (печать исключения)?**  
Да, отработает.

**Отработает ли строка `// <--` (печать "ok")?**  
Нет, не отработает.

**Объяснение:**  


fun main() {
    CoroutineScope(EmptyCoroutineContext).launch {
        try {
            supervisorScope {
                launch {
                    delay(500)
                    println("Первая корутина бросает исключение") // Выполнится
                    throw Exception("something bad happened - first") // <--
                }
                launch {
                    println("Вторая корутина бросает исключение") // Выполнится
                    throw Exception("something bad happened - second")
                }
            }
        } catch (e: Exception) {
            println("Поймано исключение: ${e.message}") // Выполнится, но message будет "something bad happened - second"
            e.printStackTrace() // <--  Отработает, но исключение будет от второй корутины
        }
    }
    Thread.sleep(1000)


    

    ***по вашему коду***
    
    fun main() {
    CoroutineScope(EmptyCoroutineContext).launch {
        try {
            supervisorScope {
                launch {
                    delay(500)
                    println("Первая корутина бросает исключение") // Выполнится
                    throw Exception("something bad happened") // <--
                }
                launch {
                    println("Вторая корутина бросает исключение") // Выполнится
                    throw Exception("something bad happened")
                }
                delay(800)
                println("done") // Отработает
            }
            println("Код после supervisorScope") // Отработает
        } catch (e: Exception) {
            println("Этот блок не будет выполнен")
            e.printStackTrace() // <-- Не отработает
        }
    }
    Thread.sleep(1000)
}

### Вопрос №6
**Отработает ли строка `// <--`?**  
Нет, не отработает.

**Объяснение:**  
Исключение в родительской корутине приведёт к отмене всех её дочерних корутин, включая те, что имеют задержку.

### Вопрос №7
**Отработает ли строка `// <--`?**  
нет не отработает

**Объяснение:**  



fun main() {
    CoroutineScope(EmptyCoroutineContext).launch {
        CoroutineScope(EmptyCoroutineContext + SupervisorJob()).launch {
            launch {
                delay(1000)
                println("ok - первая корутина") // Не отработает: отменена
            }
            launch {
                delay(500)
                println("ok - вторая корутина") // Не отработает: отменена
            }
            println("Родительская корутина бросает исключение") // Выполнится
            throw Exception("something bad happened")
        }
    }
    Thread.sleep(1000)
}

println("ok") не будет выполнена, потому что корутина, в которой она находится, будет отменена из-за исключения, брошенного её родительской корутиной (в scope с SupervisorJob).
